<?xml version="1.0" encoding="utf-8"?>
<!-- This URDF was automatically created by SolidWorks to URDF Exporter! Originally created by Stephen Brawner (brawner@gmail.com) 
     Commit Version: 1.6.0-1-g15f4949  Build Version: 1.6.7594.29634
     For more information, please see http://wiki.ros.org/sw_urdf_exporter -->
<robot
  name="amrurdf">
   <!--BASE FOOTPRINT-->
   <link name="base_link" />

  <link
    name="chassis">
    <inertial>
      <origin
        xyz="0.00018647 1.7238E-16 0.081889"
        rpy="0 0 0" />
      <mass
        value="221.87" />
      <inertia
        ixx="16.747"
        ixy="9.2541E-16"
        ixz="-0.0021388"
        iyy="37.975"
        iyz="8.9554E-16"
        izz="53.514" />
    </inertial>
    <visual>
      <origin
        xyz="0 0 0"
        rpy="0 0 0" />
      <geometry>
        <mesh
          filename="package://amrurdf/meshes/chassis.STL" />
      </geometry>
      <material
        name="">
        <color
          rgba="0.79216 0.81961 0.93333 1" />
      </material>
    </visual>
    <collision>
      <origin
        xyz="0 0 0"
        rpy="0 0 0" />
      <geometry>
        <mesh
          filename="package://amrurdf/meshes/chassis.STL" />
      </geometry>
    </collision>
  </link>

  <!--========================================== BASE JOINT ==========================================-->
  <joint name="base_joint" type="fixed">
    <origin xyz="0 0 0.2122" rpy="0 0 0" />
    <parent link="base_link" />
    <child link="chassis" />
    <axis xyz="0 0 0" />
  </joint>

  <link
    name="left_wheel">
    <inertial>
      <origin
        xyz="1.69E-18 -0.0044118 1.3878E-17"
        rpy="0 0 0" />
      <mass
        value="2.5035" />
      <inertia
        ixx="0.0078666"
        ixy="5.8713E-19"
        ixz="1.876E-19"
        iyy="0.011827"
        iyz="4.3673E-21"
        izz="0.0078666" />
    </inertial>
    <visual>
      <origin
        xyz="0 0 0"
        rpy="0 0 0" />
      <geometry>
        <mesh
          filename="package://amrurdf/meshes/left_wheel.STL" />
      </geometry>
      <material
        name="">
        <color
          rgba="0.79216 0.81961 0.93333 1" />
      </material>
    </visual>
    <collision>
      <origin
        xyz="0 0 0"
        rpy="0 0 0" />
      <geometry>
        <mesh
          filename="package://amrurdf/meshes/left_wheel.STL" />
      </geometry>
    </collision>
  </link>
  <joint
    name="left_wheel_joint"
    type="continuous">
    <origin
      xyz="0 0.396 -0.1122"
      rpy="0 0 0" />
    <parent
      link="chassis" />
    <child
      link="left_wheel" />
    <axis
      xyz="0 1 0" />
  </joint>
  <link
    name="right_wheel">
    <inertial>
      <origin
        xyz="1.8631E-18 0.0044118 1.3878E-17"
        rpy="0 0 0" />
      <mass
        value="2.5035" />
      <inertia
        ixx="0.0078666"
        ixy="-5.5234E-19"
        ixz="2.295E-35"
        iyy="0.011827"
        iyz="-1.6145E-35"
        izz="0.0078666" />
    </inertial>
    <visual>
      <origin
        xyz="0 0 0"
        rpy="0 0 0" />
      <geometry>
        <mesh
          filename="package://amrurdf/meshes/right_wheel.STL" />
      </geometry>
      <material
        name="">
        <color
          rgba="0.79216 0.81961 0.93333 1" />
      </material>
    </visual>
    <collision>
      <origin
        xyz="0 0 0"
        rpy="0 0 0" />
      <geometry>
        <mesh
          filename="package://amrurdf/meshes/right_wheel.STL" />
      </geometry>
    </collision>
  </link>
  <joint
    name="right_wheel_joint"
    type="continuous">
    <origin
      xyz="0 -0.396 -0.1122"
      rpy="0 0 0" />
    <parent
      link="chassis" />
    <child
      link="right_wheel" />
    <axis
      xyz="0 1 0" />
  </joint>
  <link
    name="imu">
    <inertial>
      <origin
        xyz="1.8078E-18 1.1975E-17 0"
        rpy="0 0 0" />
      <mass
        value="0.09" />
      <inertia
        ixx="3.375E-05"
        ixy="-3.0971E-21"
        ixz="-4.2352E-22"
        iyy="2.55E-05"
        iyz="-4.7167E-22"
        izz="4.575E-05" />
    </inertial>
    <visual>
      <origin
        xyz="0 0 0"
        rpy="0 0 0" />
      <geometry>
        <mesh
          filename="package://amrurdf/meshes/imu.STL" />
      </geometry>
      <material
        name="">
        <color
          rgba="0.79216 0.81961 0.93333 1" />
      </material>
    </visual>
    <collision>
      <origin
        xyz="0 0 0"
        rpy="0 0 0" />
      <geometry>
        <mesh
          filename="package://amrurdf/meshes/imu.STL" />
      </geometry>
    </collision>
  </link>
  <joint
    name="imu_joint"
    type="fixed">
    <origin
     xyz="0 0 0.0636" rpy="0 0 0" />   <!-- xyz="0 0 -0.015" rpy="0 0 0" />    -->  
    <parent
      link="chassis" />
    <child
      link="imu" />
    <axis
      xyz="0 0 0" />
  </joint>
  <link
    name="laser_link">
    <inertial>
      <origin
        xyz="-1.1102E-16 -5.5511E-17 0"
        rpy="0 0 0" />
      <mass
        value="0.22538" />
      <inertia
        ixx="0.00013246"
        ixy="0"
        ixz="-4.6478E-21"
        iyy="0.00013246"
        iyz="-1.5493E-21"
        izz="0.00020837" />
    </inertial>
    <visual>
      <origin
        xyz="0 0 0"
        rpy="0 0 0" />
      <geometry>
        <mesh
          filename="package://amrurdf/meshes/lidar.STL" />
      </geometry>
      <material
        name="">
        <color
          rgba="0.79216 0.81961 0.93333 1" />
      </material>
    </visual>
    <collision>
      <origin
        xyz="0 0 0"
        rpy="0 0 0" />
      <geometry>
        <mesh
          filename="package://amrurdf/meshes/lidar.STL" />
      </geometry>
    </collision>
  </link>
  <joint
    name="laser_joint"
    type="fixed">
    <origin
      xyz="0.64432 0.41352 0.0836"
      rpy="3.14 0 0.7954" />
    <parent
      link="chassis" />
    <child
      link="laser_link" />
    <axis
      xyz="0 0 0" />
  </joint>
  <link
    name="sensor">
    <inertial>
      <origin
        xyz="0 -3.3307E-16 0"
        rpy="0 0 0" />
      <mass
        value="0.059164" />
      <inertia
        ixx="1.4311E-05"
        ixy="0"
        ixz="-5.5702E-22"
        iyy="1.4311E-05"
        iyz="1.8567E-22"
        izz="1.4976E-05" />
    </inertial>
    <visual>
      <origin
        xyz="0 0 0"
        rpy="0 0 0" />
      <geometry>
        <mesh
          filename="package://amrurdf/meshes/sensor.STL" />
      </geometry>
      <material
        name="">
        <color
          rgba="0.79216 0.81961 0.93333 1" />
      </material>
    </visual>
    <collision>
      <origin
        xyz="0 0 0"
        rpy="0 0 0" />
      <geometry>
        <mesh
          filename="package://amrurdf/meshes/sensor.STL" />
      </geometry>
    </collision>
  </link>
  <joint
    name="sensor_joint"
    type="fixed">
    <origin
      xyz="-0.65598 -0.41995 0.0844"
      rpy="3.14 0 -2.3562" />
    <parent
      link="chassis" />
    <child
      link="sensor" />
    <axis
      xyz="0 0 0" />
  </joint>
  <link
    name="camera_link">
    <inertial>
      <origin
        xyz="-6.1321E-05 -7.6614E-18 -6.5648E-05"
        rpy="0 0 0" />
      <mass
        value="0.18939" />
      <inertia
        ixx="0.00041413"
        ixy="4.9425E-21"
        ixz="1.6485E-07"
        iyy="3.8773E-05"
        iyz="-6.7477E-21"
        izz="0.00042578" />
    </inertial>
    <visual>
      <origin
        xyz="0 0 0"
        rpy="0 0 0" />
      <geometry>
        <mesh
          filename="package://amrurdf/meshes/camera.STL" />
      </geometry>
      <material
        name="">
        <color
          rgba="0.79216 0.81961 0.93333 1" />
      </material>
    </visual>
    <collision>
      <origin
        xyz="0 0 0"
        rpy="0 0 0" />
      <geometry>
        <mesh
          filename="package://amrurdf/meshes/camera.STL" />
      </geometry>
    </collision>
  </link>
  <joint
    name="camera_joint"
    type="fixed">
    <origin
      xyz="0.72964 0 -0.034177"
      rpy="0 0.05236 0" />
    <parent
      link="chassis" />
    <child
      link="camera_link" />
    <axis
      xyz="0 0 0" />
  </joint>
  <link
    name="caster_front_left">
    <inertial>
      <origin
        xyz="0 0 0.061452"
        rpy="0 0 0" />
      <mass
        value="8.5066" />
      <inertia
        ixx="0.054476"
        ixy="4.8189E-35"
        ixz="1.0741E-34"
        iyy="0.054476"
        iyz="-2.4825E-18"
        izz="0.060995" />
    </inertial>
    <visual>
      <origin
        xyz="0 0 0"
        rpy="0 0 0" />
      <geometry>
        <mesh
          filename="package://amrurdf/meshes/caster_front_left.STL" />
      </geometry>
      <material
        name="">
        <color
          rgba="0.79216 0.81961 0.93333 1" />
      </material>
    </visual>
    <collision>
      <origin
        xyz="0 0 0"
        rpy="0 0 0" />
      <geometry>
        <mesh
          filename="package://amrurdf/meshes/caster_front_left.STL" />
      </geometry>
    </collision>
  </link>
  <joint
    name="caster_front_left_joint"
    type="fixed">
    <origin
      xyz="0.565 0.325 -0.14913"
      rpy="0 0 0" />
    <parent
      link="chassis" />
    <child
      link="caster_front_left" />
    <axis
      xyz="0 0 0" />
  </joint>
  <link
    name="caster_back_left">
    <inertial>
      <origin
        xyz="0 0 0.061452"
        rpy="0 0 0" />
      <mass
        value="8.5066" />
      <inertia
        ixx="0.054476"
        ixy="4.8189E-35"
        ixz="1.0741E-34"
        iyy="0.054476"
        iyz="-2.4825E-18"
        izz="0.060995" />
    </inertial>
    <visual>
      <origin
        xyz="0 0 0"
        rpy="0 0 0" />
      <geometry>
        <mesh
          filename="package://amrurdf/meshes/caster_back_left.STL" />
      </geometry>
      <material
        name="">
        <color
          rgba="0.79216 0.81961 0.93333 1" />
      </material>
    </visual>
    <collision>
      <origin
        xyz="0 0 0"
        rpy="0 0 0" />
      <geometry>
        <mesh
          filename="package://amrurdf/meshes/caster_back_left.STL" />
      </geometry>
    </collision>
  </link>
  <joint
    name="caster_back_left_joint"
    type="fixed">
    <origin
      xyz="-0.565 0.325 -0.14913"
      rpy="0 0 0" />
    <parent
      link="chassis" />
    <child
      link="caster_back_left" />
    <axis
      xyz="0 0 0" />
  </joint>
  <link
    name="caster_front_right">
    <inertial>
      <origin
        xyz="0 0 0.061452"
        rpy="0 0 0" />
      <mass
        value="8.5066" />
      <inertia
        ixx="0.054476"
        ixy="4.8189E-35"
        ixz="1.0741E-34"
        iyy="0.054476"
        iyz="-2.4825E-18"
        izz="0.060995" />
    </inertial>
    <visual>
      <origin
        xyz="0 0 0"
        rpy="0 0 0" />
      <geometry>
        <mesh
          filename="package://amrurdf/meshes/caster_front_right.STL" />
      </geometry>
      <material
        name="">
        <color
          rgba="0.79216 0.81961 0.93333 1" />
      </material>
    </visual>
    <collision>
      <origin
        xyz="0 0 0"
        rpy="0 0 0" />
      <geometry>
        <mesh
          filename="package://amrurdf/meshes/caster_front_right.STL" />
      </geometry>
    </collision>
  </link>
  <joint
    name="caster_front_right_joint"
    type="fixed">
    <origin
      xyz="0.565 -0.325 -0.14913"
      rpy="0 0 0" />
    <parent
      link="chassis" />
    <child
      link="caster_front_right" />
    <axis
      xyz="0 0 0" />
  </joint>
  <link
    name="caster_back_right">
    <inertial>
      <origin
        xyz="0 0 0.061452"
        rpy="0 0 0" />
      <mass
        value="8.5066" />
      <inertia
        ixx="0.054476"
        ixy="4.8189E-35"
        ixz="1.0741E-34"
        iyy="0.054476"
        iyz="-2.4825E-18"
        izz="0.060995" />
    </inertial>
    <visual>
      <origin
        xyz="0 0 0"
        rpy="0 0 0" />
      <geometry>
        <mesh
          filename="package://amrurdf/meshes/caster_back_right.STL" />
      </geometry>
      <material
        name="">
        <color
          rgba="0.79216 0.81961 0.93333 1" />
      </material>
    </visual>
    <collision>
      <origin
        xyz="0 0 0"
        rpy="0 0 0" />
      <geometry>
        <mesh
          filename="package://amrurdf/meshes/caster_back_right.STL" />
      </geometry>
    </collision>
  </link>
  <joint
    name="caster_back_right_joint"
    type="fixed">
    <origin
      xyz="-0.565 -0.325 -0.14913"
      rpy="0 0 0" />
    <parent
      link="chassis" />
    <child
      link="caster_back_right" />
    <axis
      xyz="0 0 0" />
  </joint>
</robot>
